<?xml version="1.0" ?>
<sdf version="1.8">
    
    <world name="car_world">
        <!-- must need this for all sensors to work-->
        <plugin name='ignition::gazebo::systems::Sensors' filename='ignition-gazebo-sensors-system'>
            <render_engine>ogre2</render_engine>
        </plugin>
        <plugin
            filename="ignition-gazebo-physics-system"
            name="ignition::gazebo::systems::Physics">
        </plugin>
        <plugin
            filename="ignition-gazebo-user-commands-system"
            name="ignition::gazebo::systems::UserCommands">
        </plugin>
        <plugin
            filename="ignition-gazebo-scene-broadcaster-system"
            name="ignition::gazebo::systems::SceneBroadcaster">
        </plugin>
        <plugin filename="libignition-gazebo-imu-system.so"
        name="ignition::gazebo::systems::Imu">
        </plugin>
        <!-- -->
        <gui fullscreen='false'>
            <plugin name='3D View' filename='GzScene3D'>
              <ignition-gui>
                <title>3D View</title>
                <property type='bool' key='showTitleBar'>false</property>
                <property type='string' key='state'>docked</property>
              </ignition-gui>
              <engine>ogre2</engine>
              <scene>scene</scene>
              <ambient_light>0.4 0.4 0.4</ambient_light>
              <background_color>0.5 0.8 0.95</background_color>
              <camera_follow>
                <target>vehicle_blue</target>
                <p_gain>0.5</p_gain>
                <offset>-5 0 2</offset>
              </camera_follow>
            </plugin>
            <plugin name='World control' filename='WorldControl'>
              <ignition-gui>
                <title>World control</title>
                <property type='bool' key='showTitleBar'>false</property>
                <property type='bool' key='resizable'>false</property>
                <property type='double' key='height'>72</property>
                <property type='double' key='width'>121</property>
                <property type='double' key='z'>1</property>
                <property type='string' key='state'>floating</property>
                <anchors target='3D View'>
                  <line own='left' target='left'/>
                  <line own='bottom' target='bottom'/>
                </anchors>
              </ignition-gui>
              <play_pause>true</play_pause>
              <step>true</step>
              <start_paused>true</start_paused>
            </plugin>
            <plugin name='World stats' filename='WorldStats'>
              <ignition-gui>
                <title>World stats</title>
                <property type='bool' key='showTitleBar'>false</property>
                <property type='bool' key='resizable'>false</property>
                <property type='double' key='height'>110</property>
                <property type='double' key='width'>290</property>
                <property type='double' key='z'>1</property>
                <property type='string' key='state'>floating</property>
                <anchors target='3D View'>
                  <line own='right' target='right'/>
                  <line own='bottom' target='bottom'/>
                </anchors>
              </ignition-gui>
              <sim_time>true</sim_time>
              <real_time>true</real_time>
              <real_time_factor>true</real_time_factor>
              <iterations>true</iterations>
            </plugin>
            <plugin name='dis' filename='ImageDisplay'>
              <ignition-gui>
                <property key='state' type='string'>docked</property>
              </ignition-gui>
              <topic>front_camera</topic>
            </plugin>
            <plugin name='Teleop' filename='Teleop'>
              <ignition-gui>
                <property type='string' key='state'>docked</property>
              </ignition-gui>
              <topic>/cmd_vel</topic>
            </plugin>
        </gui>

        <!--- -->
        <gravity>0 0 -9.8</gravity>
        <magnetic_field>6e-06 2.3e-05 -4.2e-05</magnetic_field>
        <atmosphere type='adiabatic'/>
        <physics type='ode'>
          <max_step_size>0.001</max_step_size>
          <real_time_factor>1</real_time_factor>
          <real_time_update_rate>1000</real_time_update_rate>
        </physics>
        
        <light type="directional" name="sun">
            <cast_shadows>true</cast_shadows>
            <pose>0 0 10 0 0 0</pose>
            <diffuse>0.8 0.8 0.8 1</diffuse>
            <specular>0.2 0.2 0.2 1</specular>
            <attenuation>
                <range>1000</range>
                <constant>0.9</constant>
                <linear>0.01</linear>
                <quadratic>0.001</quadratic>
            </attenuation>
            <direction>-0.5 0.1 -0.9</direction>
        </light>
        <!-- <include>
            <uri>
            https://fuel.gazebosim.org/1.0/OpenRobotics/models/Parking garage
            </uri>
            <scale>0.01 0.01 0.01</scale>
        </include> -->

        <model name="ground_plane">
            <static>true</static>
            <link name="link">
                <collision name="collision">
                <geometry>
                    <plane>
                    <normal>0 0 1</normal>
                    </plane>
                </geometry>
                </collision>
                <visual name="visual">
                <geometry>
                    <plane>
                    <normal>0 0 1</normal>
                    <size>100 100</size>
                    </plane>
                </geometry>
                <material>
                    <ambient>0.8 0.8 0.8 1</ambient>
                    <diffuse>0.8 0.8 0.8 1</diffuse>
                    <specular>0.8 0.8 0.8 1</specular>
                </material>
                </visual>
            </link>
        </model>

        <model name="simple_wall">
            <static>true</static> <!-- Makes the wall non-movable -->
            <pose>3 2 0 0 0 0</pose> <!-- x, y, z position and roll, pitch, yaw orientation -->
            <link name="wall_link">
              <collision name="wall_collision">
                <geometry>
                  <box>
                    <size>5 0.2 2.5</size> <!-- Width, Depth, Height -->
                  </box>
                </geometry>
                <surface>
                  <contact>
                    <collide_without_contact>true</collide_without_contact>
                  </contact>
                </surface>
              </collision>
        
              <visual name="wall_visual">
                <geometry>
                  <box>
                    <size>5 0.2 2.5</size> <!-- Width, Depth, Height -->
                  </box>
                </geometry>
                <material>
                  <ambient>0.7 0.7 0.7 1</ambient> <!-- Gray color -->
                  <diffuse>0.7 0.7 0.7 1</diffuse>
                  <specular>0.1 0.1 0.1 1</specular>
                </material>
              </visual>
            </link>
        </model>

        <model name='vehicle_blue' canonical_link='chassis'>
            <pose relative_to='world'>0 0 0 0 0 0</pose>   <!--the pose is relative to the world by default-->

            <!--chassis-->
            <link name='chassis'>
                <pose relative_to='__model__'>0.0 0 0.2 0 0 0</pose>
                <sensor name="imu_sensor" type="imu">
                    <always_on>1</always_on>
                    <update_rate>1</update_rate>
                    <visualize>true</visualize>
                    <topic>imu</topic>
                </sensor>
                <visual name='visual'>
                    <geometry>
                        <mesh>
                            <uri>file://new_car_chassis.stl</uri>
                            <scale>0.58 0.58 0.58</scale>
                        </mesh>
                    </geometry>
                    <!--Color of the link-->
                    <material>
                        <ambient>0.0 0.0 1.0 1</ambient>
                        <diffuse>0.0 0.0 1.0 1</diffuse>
                        <specular>0.0 0.0 1.0 1</specular>
                    </material>
                </visual>
                <collision name='collision'>
                    <geometry>
                        <mesh>
                            <uri>file://new_car_chassis.stl</uri>
                            <scale>0.58 0.58 0.58</scale>
                        </mesh>
                    </geometry>
                </collision>
                <!-- Cameras -->
                <sensor name='front_camera_sensor' type='camera'>
                    <pose>0.27 0 1.1 0 0 0</pose>
                    <topic>front_camera</topic>
                    <update_rate>30</update_rate>
                    <enable_metrics>false</enable_metrics>
                    <camera name='front_camera'>
                        <pose>0 0 0 0 -0 0</pose>
                        <horizontal_fov>1.3962600000000001</horizontal_fov>
                        <image>
                            <width>800</width>
                            <height>800</height>
                            <format>RGB_INT8</format>
                            <anti_aliasing>4</anti_aliasing>
                        </image>
                        <camera_info_topic>__default__</camera_info_topic>
                        <trigger_topic></trigger_topic>
                        <triggered>false</triggered>
                        <clip>
                            <near>0.02</near>
                            <far>300</far>
                        </clip>
                    <save enabled='false'>
                        <path>__default__</path>
                    </save>
                    <visibility_mask>4294967295</visibility_mask>
                    <noise>
                        <type>gaussian</type>
                        <mean>0</mean>
                        <stddev>0.0070000000000000001</stddev>
                    </noise>
                    <distortion>
                        <k1>0</k1>
                        <k2>0</k2>
                        <k3>0</k3>
                        <p1>0</p1>
                        <p2>0</p2>
                        <center>0.5 0.5</center>
                    </distortion>
                    <lens>
                        <type>stereographic</type>
                        <scale_to_hfov>true</scale_to_hfov>
                        <cutoff_angle>1.5708</cutoff_angle>
                        <env_texture_size>256</env_texture_size>
                    </lens>
                    <optical_frame_id></optical_frame_id>
                    </camera>
                </sensor>
                <sensor name='back_camera_sensor' type='camera'>
                    <pose>-0.47 0 1.1 0 0 3.1415</pose>
                    <topic>back_camera</topic>
                    <update_rate>30</update_rate>
                    <enable_metrics>false</enable_metrics>
                    <camera name='back_camera'>
                        <pose>0 0 0 0 -0 0</pose>
                        <horizontal_fov>1.3962600000000001</horizontal_fov>
                        <image>
                            <width>800</width>
                            <height>800</height>
                            <format>RGB_INT8</format>
                            <anti_aliasing>4</anti_aliasing>
                        </image>
                        <camera_info_topic>__default__</camera_info_topic>
                        <trigger_topic></trigger_topic>
                        <triggered>false</triggered>
                        <clip>
                            <near>0.02</near>
                            <far>300</far>
                        </clip>
                        <save enabled='false'>
                            <path>__default__</path>
                        </save>
                        <visibility_mask>4294967295</visibility_mask>
                        <noise>
                            <type>gaussian</type>
                            <mean>0</mean>
                            <stddev>0.0070000000000000001</stddev>
                        </noise>
                        <distortion>
                            <k1>0</k1>
                            <k2>0</k2>
                            <k3>0</k3>
                            <p1>0</p1>
                            <p2>0</p2>
                            <center>0.5 0.5</center>
                        </distortion>
                        <lens>
                            <type>stereographic</type>
                            <scale_to_hfov>true</scale_to_hfov>
                            <cutoff_angle>1.5708</cutoff_angle>
                            <env_texture_size>256</env_texture_size>
                        </lens>
                        <optical_frame_id></optical_frame_id>
                    </camera>
                </sensor>
                <sensor name='left_camera_sensor' type='camera'>
                    <pose>-0.2 0.28 1.1 0 0 0.785</pose>
                    <topic>left_camera</topic>
                    <update_rate>30</update_rate>
                    <enable_metrics>false</enable_metrics>
                    <camera name='left_camera'>
                      <pose>0 0 0 0 -0 0</pose>
                      <horizontal_fov>1.3962600000000001</horizontal_fov>
                      <image>
                        <width>800</width>
                        <height>800</height>
                        <format>RGB_INT8</format>
                        <anti_aliasing>4</anti_aliasing>
                      </image>
                      <camera_info_topic>__default__</camera_info_topic>
                      <trigger_topic></trigger_topic>
                      <triggered>false</triggered>
                      <clip>
                        <near>0.02</near>
                        <far>300</far>
                      </clip>
                      <save enabled='false'>
                        <path>__default__</path>
                      </save>
                      <visibility_mask>4294967295</visibility_mask>
                      <noise>
                        <type>gaussian</type>
                        <mean>0</mean>
                        <stddev>0.0070000000000000001</stddev>
                      </noise>
                      <distortion>
                        <k1>0</k1>
                        <k2>0</k2>
                        <k3>0</k3>
                        <p1>0</p1>
                        <p2>0</p2>
                        <center>0.5 0.5</center>
                      </distortion>
                      <lens>
                        <type>stereographic</type>
                        <scale_to_hfov>true</scale_to_hfov>
                        <cutoff_angle>1.5708</cutoff_angle>
                        <env_texture_size>256</env_texture_size>
                      </lens>
                      <optical_frame_id></optical_frame_id>
                    </camera>
                  </sensor>
                  <sensor name='right_camera_sensor' type='camera'>
                    <pose>-0.2 -0.28 1.1 0 0 -0.785</pose>
                    <topic>right_camera</topic>
                    <update_rate>30</update_rate>
                    <enable_metrics>false</enable_metrics>
                    <camera name='right_camera'>
                      <pose>0 0 0 0 -0 0</pose>
                      <horizontal_fov>1.3962600000000001</horizontal_fov>
                      <image>
                        <width>800</width>
                        <height>800</height>
                        <format>RGB_INT8</format>
                        <anti_aliasing>4</anti_aliasing>
                      </image>
                      <camera_info_topic>__default__</camera_info_topic>
                      <trigger_topic></trigger_topic>
                      <triggered>false</triggered>
                      <clip>
                        <near>0.02</near>
                        <far>300</far>
                      </clip>
                      <save enabled='false'>
                        <path>__default__</path>
                      </save>
                      <visibility_mask>4294967295</visibility_mask>
                      <noise>
                        <type>gaussian</type>
                        <mean>0</mean>
                        <stddev>0.0070000000000000001</stddev>
                      </noise>
                      <distortion>
                        <k1>0</k1>
                        <k2>0</k2>
                        <k3>0</k3>
                        <p1>0</p1>
                        <p2>0</p2>
                        <center>0.5 0.5</center>
                      </distortion>
                      <lens>
                        <type>stereographic</type>
                        <scale_to_hfov>true</scale_to_hfov>
                        <cutoff_angle>1.5708</cutoff_angle>
                        <env_texture_size>256</env_texture_size>
                      </lens>
                      <optical_frame_id></optical_frame_id>
                    </camera>
                  </sensor>
            </link>
            <link name='front_camera_marker'>
                <pose>0.27 0 1.1 0 0 0</pose> <!-- Adjust this pose to match the camera's pose -->
                <collision name='camera_marker_collision'>
                    <geometry>
                        <box>
                            <size>0.04 0.04 0.04</size> <!-- Size of the block -->
                        </box>
                    </geometry>
                </collision>
                <visual name='front_camera_marker'>
                    <geometry>
                        <box>
                            <size>0.04 0.04 0.04</size> <!-- Size of the block -->
                        </box>
                    </geometry>
                    <material>
                        <ambient>0.5 0.5 0.5 1</ambient>
                        <diffuse>0.5 0.5 0.5 1</diffuse>
                        <specular>0.5 0.5 0.5 1</specular>
                    </material>
                </visual>
            </link>
            <link name='back_camera_marker'>
                <pose>-0.47 0 1.1 0 0 3.1415</pose> <!-- Adjust this pose to match the camera's pose -->
                <collision name='camera_marker_collision'>
                    <geometry>
                        <box>
                            <size>0.04 0.04 0.04</size> <!-- Size of the block -->
                        </box>
                    </geometry>
                </collision>
                <visual name='back_camera_marker'>
                    <geometry>
                        <box>
                            <size>0.04 0.04 0.04</size> <!-- Size of the block -->
                        </box>
                    </geometry>
                    <material>
                        <ambient>0.5 0.5 0.5 1</ambient>
                        <diffuse>0.5 0.5 0.5 1</diffuse>
                        <specular>0.5 0.5 0.5 1</specular>
                    </material>
                </visual>
            </link>
            <link name='left_camera_marker'>
                <pose>-0.2 0.28 1.1 0 0 0.785</pose> <!-- Adjust this pose to match the camera's pose -->
                <collision name='camera_marker_collision'>
                    <geometry>
                        <box>
                            <size>0.04 0.04 0.04</size> <!-- Size of the block -->
                        </box>
                    </geometry>
                </collision>
                <visual name='left_camera_marker'>
                    <geometry>
                        <box>
                            <size>0.04 0.04 0.04</size> <!-- Size of the block -->
                        </box>
                    </geometry>
                    <material>
                        <ambient>0.5 0.5 0.5 1</ambient>
                        <diffuse>0.5 0.5 0.5 1</diffuse>
                        <specular>0.5 0.5 0.5 1</specular>
                    </material>
                </visual>
            </link>
            <link name='right_camera_marker'>
                <pose>-0.2 -0.28 1.1 0 0 -0.785</pose> <!-- Adjust this pose to match the camera's pose -->
                <collision name='camera_marker_collision'>
                    <geometry>
                        <box>
                            <size>0.04 0.04 0.04</size> <!-- Size of the block -->
                        </box>
                    </geometry>
                </collision>
                <visual name='right_camera_marker'>
                    <geometry>
                        <box>
                            <size>0.04 0.04 0.04</size> <!-- Size of the block -->
                        </box>
                    </geometry>
                    <material>
                        <ambient>0.5 0.5 0.5 1</ambient>
                        <diffuse>0.5 0.5 0.5 1</diffuse>
                        <specular>0.5 0.5 0.5 1</specular>
                    </material>
                </visual>
            </link>   
            
            <!-- WHEELS  -->
            <!--rear Left wheel-->
            <link name='rear_left_wheel'>
                <pose relative_to="chassis">-0.6 0.42 0 -1.5707 0 0</pose> <!--angles are in radian-->
                <inertial>
                    <mass>7</mass>
                    <inertia>
                        <ixx>0.086858</ixx>
                        <ixy>0</ixy>
                        <ixz>0</ixz>
                        <iyy>0.086858</iyy>
                        <iyz>0</iyz>
                        <izz>0.14</izz>
                    </inertia>
                </inertial>
                <visual name='visual'>
                    <geometry>
                        <cylinder>
                            <radius>0.2</radius>
                            <length>0.17</length>
                        </cylinder>
                    </geometry>
                    <material>
                        <ambient>0.0 0.0 0.0 1</ambient>
                        <diffuse>0.0 0.0 0.0 1</diffuse>
                        <specular>0.0 0.0 0.0 1</specular>
                    </material>
                </visual>
                <collision name='collision'>
                    <geometry>
                        <cylinder>
                            <radius>0.2</radius>
                            <length>0.17</length>
                        </cylinder>
                    </geometry>
                </collision>
            </link>

            <!--The same as left wheel but with different position-->
            <link name='rear_right_wheel'>
                <pose relative_to="chassis">-0.6 -0.42 0 -1.5707 0 0</pose> <!--angles are in radian-->
                <inertial>
                    <mass>7</mass>
                    <inertia>
                        <ixx>0.086858</ixx>
                        <ixy>0</ixy>
                        <ixz>0</ixz>
                        <iyy>0.086858</iyy>
                        <iyz>0</iyz>
                        <izz>0.14</izz>
                    </inertia>
                </inertial>
                <visual name='visual'>
                    <geometry>
                        <cylinder>
                            <radius>0.2</radius>
                            <length>0.17</length>
                        </cylinder>
                    </geometry>
                    <material>
                        <ambient>0.0 0.0 0.0 1</ambient>
                        <diffuse>0.0 0.0 0.0 1</diffuse>
                        <specular>0.0 0.0 0.0 1</specular>
                    </material>
                </visual>
                <collision name='collision'>
                    <geometry>
                        <cylinder>
                            <radius>0.2</radius>
                            <length>0.17</length>
                        </cylinder>
                    </geometry>
                </collision>
            </link>

            <!--front Left wheel-->
            <link name='front_left_wheel'>
                <pose relative_to="chassis">0.6 0.45 0 -1.5707 0 0</pose> <!--angles are in radian-->
                <inertial>
                    <mass>5</mass>
                    <inertia>
                        <ixx>0.057042</ixx>
                        <ixy>0</ixy>
                        <ixz>0</ixz>
                        <iyy>0.057042</iyy>
                        <iyz>0</iyz>
                        <izz>0.1</izz>
                    </inertia>
                </inertial>
                <visual name='visual'>
                    <geometry>
                        <cylinder>
                            <radius>0.2</radius>
                            <length>0.13</length>
                        </cylinder>
                    </geometry>
                    <material>
                        <ambient>0.0 0.0 0.0 1</ambient>
                        <diffuse>0.0 0.0 0.0 1</diffuse>
                        <specular>0.0 0.0 0.0 1</specular>
                    </material>
                </visual>
                <collision name='collision'>
                    <geometry>
                        <cylinder>
                            <radius>0.2</radius>
                            <length>0.13</length>
                        </cylinder>
                    </geometry>
                </collision>
            </link>

            <!--front Left wheel-->
            <link name='front_right_wheel'>
                <pose relative_to="chassis">0.6 -0.45 0 -1.5707 0 0</pose> <!--angles are in radian-->
                <inertial>
                    <mass>5</mass>
                    <inertia>
                        <ixx>0.057042</ixx>
                        <ixy>0</ixy>
                        <ixz>0</ixz>
                        <iyy>0.057042</iyy>
                        <iyz>0</iyz>
                        <izz>0.1</izz>
                    </inertia>
                </inertial>
                <visual name='visual'>
                    <geometry>
                        <cylinder>
                            <radius>0.2</radius>
                            <length>0.13</length>
                        </cylinder>
                    </geometry>
                    <material>
                        <ambient>0.0 0.0 0.0 1</ambient>
                        <diffuse>0.0 0.0 0.0 1</diffuse>
                        <specular>0.0 0.0 0.0 1</specular>
                    </material>
                </visual>
                <collision name='collision'>
                    <geometry>
                        <cylinder>
                            <radius>0.2</radius>
                            <length>0.13</length>
                        </cylinder>
                    </geometry>
                </collision>
            </link>
            
            
            <!-- - - - - - - - - - - - - - - - - LINKAGE - - - - - - - -  - - - - - - - - - - -->
            <!--front left wheel steering link-->
            <link name='front_left_steering_link'>
                <pose relative_to='front_left_wheel'/>
                <inertial>
                    <mass>0.5</mass>
                    <inertia>
                      <ixx>0.015299999999999999</ixx>
                      <iyy>0.025000000000000001</iyy>
                      <izz>0.015299999999999999</izz>
                      <ixy>0</ixy>
                      <ixz>0</ixz>
                      <iyz>0</iyz>
                    </inertia>
                    <pose>0 0 0 0 -0 0</pose>
                  </inertial>
                  <enable_wind>false</enable_wind>
            </link>

            <!--front right wheel link-->
            <link name='front_right_steering_link'>
                <pose relative_to='front_right_wheel'/>
                <inertial>
                    <mass>0.5</mass>
                    <inertia>
                      <ixx>0.015299999999999999</ixx>
                      <iyy>0.025000000000000001</iyy>
                      <izz>0.015299999999999999</izz>
                      <ixy>0</ixy>
                      <ixz>0</ixz>
                      <iyz>0</iyz>
                    </inertia>
                    <pose>0 0 0 0 -0 0</pose>
                  </inertial>
                  <enable_wind>false</enable_wind>
            </link>

            <!--front left steering joint-->
            <joint name='front_left_steering_joint' type='revolute'>
                <parent>chassis</parent>
                <child>front_left_steering_link</child>
                <axis>
                    <xyz expressed_in='__model__'>0 0 1</xyz> <!-- z-axis for steering -->
                    <limit>
                        <lower>-1.79769e+308</lower>    <!--negative infinity-->
                        <upper>1.79769e+308</upper>     <!--positive infinity-->
                    </limit>
                </axis>
            </joint>

            <!--front right steering joint-->
            <joint name='front_right_steering_joint' type='revolute'>
                <parent>chassis</parent>
                <child>front_right_steering_link</child>
                <axis>
                    <xyz expressed_in='__model__'>0 0 1</xyz> <!-- z-axis for steering -->
                    <limit>
                        <lower>-1.79769e+308</lower>    <!--negative infinity-->
                        <upper>1.79769e+308</upper>     <!--positive infinity-->
                    </limit>
                </axis>
            </joint>
            
            <!-- - - - - - - - - - - - - -DEFINING JOINTS - - - - - - - - - - - - - - - - - -->
            <!--rear left wheel joint-->
            <joint name='rear_left_wheel_joint' type='revolute'>
                <pose relative_to='rear_left_wheel'/>
                <parent>chassis</parent>
                <child>rear_left_wheel</child>
                <axis>
                    <xyz expressed_in='__model__'>0 1 0</xyz> <!--can be descired to any frame or even arbitrary frames-->
                    <limit>
                        <lower>-1.79769e+308</lower>    <!--negative infinity-->
                        <upper>1.79769e+308</upper>     <!--positive infinity-->
                    </limit>
                </axis>
            </joint>

            <!--rear right wheel joint-->
            <joint name='rear_right_wheel_joint' type='revolute'>
                <pose relative_to='rear_right_wheel'/>
                <parent>chassis</parent>
                <child>rear_right_wheel</child>
                <axis>
                    <xyz expressed_in='__model__'>0 1 0</xyz>
                    <limit>
                        <lower>-1.79769e+308</lower>    <!--negative infinity-->
                        <upper>1.79769e+308</upper>     <!--positive infinity-->
                    </limit>
                </axis>
            </joint>

            <!--front left wheel joint-->
            <joint name='front_left_wheel_joint' type='revolute'>
                <pose relative_to='front_left_wheel'/>
                <parent>front_left_steering_link</parent>
                <child>front_left_wheel</child>
                <axis>
                    <xyz expressed_in='__model__'>0 1 0</xyz> <!--can be descired to any frame or even arbitrary frames-->
                    <limit>
                        <lower>-1.79769e+308</lower>    <!--negative infinity-->
                        <upper>1.79769e+308</upper>     <!--positive infinity-->
                    </limit>
                </axis>
            </joint>

            <!--front right wheel joint-->
            <joint name='front_right_wheel_joint' type='revolute'>
                <pose relative_to='front_right_wheel'/>
                <parent>front_right_steering_link</parent>
                <child>front_right_wheel</child>
                <axis>
                    <xyz expressed_in='__model__'>0 1 0</xyz> <!--can be descired to any frame or even arbitrary frames-->
                    <limit>
                        <lower>-1.79769e+308</lower>    <!--negative infinity-->
                        <upper>1.79769e+308</upper>     <!--positive infinity-->
                    </limit>
                </axis>
            </joint>

            <joint name='front_camera_joint' type='fixed'>
                <parent>chassis</parent>
                <child>front_camera_marker</child>
                <pose>0.27 0 1.1 0 0 0</pose> <!-- Adjust this pose if necessary -->
            </joint>
            <joint name='back_camera_joint' type='fixed'>
                <parent>chassis</parent>
                <child>back_camera_marker</child>
                <pose>-0.47 0 1.1 0 0 3.1415</pose> <!-- Adjust this pose if necessary -->
            </joint>
            <joint name='left_camera_joint' type='fixed'>
                <parent>chassis</parent>
                <child>left_camera_marker</child>
                <pose>-0.2 0.28 1.1 0 0 0.785</pose> <!-- Adjust this pose if necessary -->
            </joint>
            <joint name='right_camera_joint' type='fixed'>
                <parent>chassis</parent>
                <child>right_camera_marker</child>
                <pose>-0.2 -0.28 1.1 0 0 -0.785</pose> <!-- Adjust this pose if necessary -->
            </joint>
            <plugin name='ignition::gazebo::systems::AckermannSteering' filename='ignition-gazebo-ackermann-steering-system'>
                <topic>/cmd_vel</topic>
                <left_joint>front_left_wheel_joint</left_joint>
                <left_joint>rear_left_wheel_joint</left_joint>
                <right_joint>front_right_wheel_joint</right_joint>
                <right_joint>rear_right_wheel_joint</right_joint>
                <left_steering_joint>front_left_steering_joint</left_steering_joint>
                <right_steering_joint>front_right_steering_joint</right_steering_joint>
                <kingpin_width>0.75</kingpin_width>
                <steering_limit>0.5</steering_limit>
                <wheel_base>1.25</wheel_base>
                <wheel_separation>0.9</wheel_separation>
                <wheel_radius>0.2</wheel_radius>
                <min_velocity>-10</min_velocity>
                <max_velocity>100</max_velocity>
                <min_acceleration>-30</min_acceleration>
                <max_acceleration>30</max_acceleration>
            </plugin>
            <static>false</static>
            <self_collide>false</self_collide>    
        </model>
    </world>
</sdf>
